Workbook
Name IQ_CH: 110000
Name IQ_CQ: 5000
Name IQ_CY: 10000
Name IQ_DAILY: 500000
Name IQ_FH: 100000
Name IQ_FQ: 500
Name IQ_FY: 1000
Name IQ_LTM: 2000
Name IQ_MONTH: 15000
Name IQ_NTM: 6000
Name IQ_WEEK: 50000
Name IQ_YTD: 3000

Sheet Data
A1: # | B1: Date | C1: Author | D1: Publication | E1: Title | F1: First Paragraph | G1: Anti-Semitic | H1: Not Anti-Semitic | I1: Anti-Israel | J1: Anti-Palestinian | K1: Not Anti-Palestinian | L1: Anti-Hamas | M1: Op-Ed | N1: Anti-Semtic Reason1 | O1: Anti-Semtic Reason2 | P1: title_word_count | Q1: First_Para_word_count | R1: Title_Sentiment | S1: First800_Sentiment | T1: Last4Sent_Sentiment | U1: Netanyahu_FirstPara_Sentiment | V1: Bibi_FirstPara_Sentiment | W1: Hamas_FirstPara_Sentiment | X1: Israel_FirstPara_Sentiment | Y1: Palestinian_FirstPara_Sentiment | Z1: Gaza_FirstPara_Sentiment | AA1: Ceasefire_FirstPara_Sentiment | AB1: Trump_FirstPara_Sentiment | AC1: Combined_Sentiment | AD1: text_combined_weighted | AE1: Date_dt | AF1: Date_display | AG1: Year | AH1: term1 | AI1: term2 | AJ1: term3
A2: 1 | B2: 45952 | C2: Bret Stephens | D2: The New York Times | E2: Why Mamdani Frightens Jews Like Me | F2: A recent Fox News poll found that 38 percent of Jewish New Yorkers intend to vote for Zohran Mamdani for mayor, setting aside whatever reservations they might have about the candidateâ€™s views on Israel. At least a few of those voters will support the 34-year-old state assemblyman not despite those views, but because of them | G2: 0 | H2: 0 | I2: 0 | J2: 0 | K2: 0 | L2: 0 | M2: 1 | N2: 0 | O2: 0 | P2: 6 | Q2: 55 | R2: 0.112 | S2: 0.653 | T2: 0.653 | U2: 0.5 | V2: 0.5 | W2: 0.5 | X2: 0.585 | Y2: 0.5 | Z2: 0.5 | AA2: 0.5 | AB2: 0.5 | AC2: 0.3825 | AD2: Title: Why Mamdani Frightens Jews Like Me. Title: Why Mamdani Frightens Jews Like Me. First Paragraph: A recent Fox News poll found that 38 percent of Jewish New Yorkers intend to vote for Zohran Mamdani for mayor, setting aside whatever reservations they might have about the candidateâ€™s views on Israel. At least a few of those voters will support the 34-year-old state assemblyman not despite those views, but because of them | AE2: 45952 | AF2: 45952 | AG2: 2025 | AH2: israel | AI2: jews | AJ2: hamas
A3: 2 | B3: 45944 | C3: Bret Stephens | D3: The New York Times | E3: Why Israel Won the War | F3: Though it seems absurd in retrospect, there were many in Hamas who believed their massacre of Oct. 7, 2023, would succeed not just in wounding Israel but in destroying it. | G3: 0 | H3: 0 | I3: 0 | J3: 0 | K3: 0 | L3: 0 | M3: 1 | N3: 0 | O3: 0 | P3: 5 | Q3: 30 | R3: 0.391 | S3: 0.064 | T3: 0.064 | U3: 0.5 | V3: 0.5 | W3: 0.064 | X3: 0.064 | Y3: 0.5 | Z3: 0.5 | AA3: 0.5 | AB3: 0.5 | AC3: 0.2275 | AD3: Title: Why Israel Won the War. Title: Why Israel Won the War. First Paragraph: Though it seems absurd in retrospect, there were many in Hamas who believed their massacre of Oct. 7, 2023, would succeed not just in wounding Israel but in destroying it. | AE3: 45944 | AF3: 45944 | AG3: 2025 | AH3: israel | AI3: jews | AJ3: hamas
A4: 3 | B4: 45937 | C4: Bret Stephens | D4: The New York Times | E4: What Israel Should Learn From Two Years of War | F4: Maya Angelouâ€™s classic warning should have been believed in 1988, when Hamas declared in its founding covenant its intention to slaughter Jews. Instead, Israel continued to tolerate Hamas out of a combination of ideological convenience â€” it suited Benjamin Netanyahu, the Israeli prime minister, to have a divided Palestinian polity â€” and international reluctance to topple the group. That was until Oct. 7, 2023, too late for the 1,200 people slaughtered that day. | G4: 0 | H4: 0 | I4: 0 | J4: 0 | K4: 0 | L4: 0 | M4: 1 | N4: 0 | O4: 0 | P4: 9 | Q4: 73 | R4: 0.181 | S4: 0.204 | T4: 0.204 | U4: 0.131 | V4: 0.5 | W4: 0.208 | X4: 0.131 | Y4: 0.131 | Z4: 0.5 | AA4: 0.5 | AB4: 0.5 | AC4: 0.1925 | AD4: Title: What Israel Should Learn From Two Years of War. Title: What Israel Should Learn From Two Years of War. First Paragraph: Maya Angelouâ€™s classic warning should have been believed in 1988, when Hamas declared in its founding covenant its intention to slaughter Jews. Instead, Israel continued to tolerate Hamas out of a combination of ideological convenience â€” it suited Benjamin Netanyahu, the Israeli prime minister, to have a divided Palestinian polity â€” and international reluctance to topple the group. That was until Oct. 7, 2023, too late for the 1,200 people slaughtered that day. | AE4: 45937 | AF4: 45937 | AG4: 2025 | AH4: israel | AI4: jews | AJ4: hamas
A5: 4 | B5: 45909 | C5: Bret Stephens | D5: The New York Times | E5: Gesture Politics Wonâ€™t Help Palestinians | F5: This month, France, Canada, Australia and possibly Britain will recognize a Palestinian state at the United Nations General Assembly. Also, some 1,800 actors and filmmakers, including Mark Ruffalo and Cynthia Nixon, have signed a public letter pledging â€œnot to screen films, appear at or otherwise work with Israeli film institutions.â€ And the government of Spain imposed an arms embargo on Israel. | G5: 0 | H5: 0 | I5: 0 | J5: 0 | K5: 0 | L5: 0 | M5: 1 | N5: 0 | O5: 0 | P5: 5 | Q5: 61 | R5: 0.059 | S5: 0.475 | T5: 0.475 | U5: 0.5 | V5: 0.5 | W5: 0.5 | X5: 0.142 | Y5: 0.564 | Z5: 0.5 | AA5: 0.5 | AB5: 0.5 | AC5: 0.267 | AD5: Title: Gesture Politics Wonâ€™t Help Palestinians. Title: Gesture Politics Wonâ€™t Help Palestinians. First Paragraph: This month, France, Canada, Australia and possibly Britain will recognize a Palestinian state at the United Nations General Assembly. Also, some 1,800 actors and filmmakers, including Mark Ruffalo and Cynthia Nixon, have signed a public letter pledging â€œnot to screen films, appear at or otherwise work with Israeli film institutions.â€ And the government of Spain imposed an arms embargo on Israel. | AE5: 45909 | AF5: 45909 | AG5: 2025 | AH5: israel | AI5: jews | AJ5: hamas
A6: 5 | B6: 45874 | C6: Bret Stephens | D6: The New York Times | E6: Where Can Gaza Go From Here? | F6: First and most obviously: The government of Israel needs to rush, in abundant quantities and to immediate and undeniable effect, food and medicine to the places in Gaza that desperately need them. | G6: 0 | H6: 0 | I6: 0 | J6: 0 | K6: 0 | L6: 0 | M6: 1 | N6: 0 | O6: 0 | P6: 6 | Q6: 32 | R6: 0.29 | S6: 0.349 | T6: 0.349 | U6: 0.5 | V6: 0.5 | W6: 0.5 | X6: 0.349 | Y6: 0.5 | Z6: 0.349 | AA6: 0.5 | AB6: 0.5 | AC6: 0.3195 | AD6: Title: Where Can Gaza Go From Here?. Title: Where Can Gaza Go From Here?. First Paragraph: First and most obviously: The government of Israel needs to rush, in abundant quantities and to immediate and undeniable effect, food and medicine to the places in Gaza that desperately need them. | AE6: 45874 | AF6: 45874 | AG6: 2025 | AH6: israel | AI6: jews | AJ6: hamas
A7: 6 | B7: 45860 | C7: Bret Stephens | D7: The New York Times | E7: No, Israel Is Not Committing Genocide in Gaza | F7: It may seem harsh to say, but there is a glaring dissonance to the charge that Israel is committing genocide in Gaza. To wit: If the Israeli governmentâ€™s intentions and actions are truly genocidal â€” if it is so malevolent that it is committed to the annihilation of Gazans â€” why hasnâ€™t it been more methodical and vastly more deadly? Why not, say, hundreds of thousands of deaths, as opposed to the nearly 60,000 that Gazaâ€™s Hamas-run Health Ministry, which does not distinguish between combatant and civilian deaths, has cited so far in nearly two years of war? | G7: 0 | H7: 0 | I7: 0 | J7: 0 | K7: 0 | L7: 0 | M7: 1 | N7: 0 | O7: 0 | P7: 8 | Q7: 98 | R7: 0.19 | S7: 0.099 | T7: 0.099 | U7: 0.5 | V7: 0.5 | W7: 0.114 | X7: 0.069 | Y7: 0.5 | Z7: 0.092 | AA7: 0.5 | AB7: 0.5 | AC7: 0.1445 | AD7: Title: No, Israel Is Not Committing Genocide in Gaza. Title: No, Israel Is Not Committing Genocide in Gaza. First Paragraph: It may seem harsh to say, but there is a glaring dissonance to the charge that Israel is committing genocide in Gaza. To wit: If the Israeli governmentâ€™s intentions and actions are truly genocidal â€” if it is so malevolent that it is committed to the annihilation of Gazans â€” why hasnâ€™t it been more methodical and vastly more deadly? Why not, say, hundreds of thousands of deaths, as opposed to the nearly 60,000 that Gazaâ€™s Hamas-run Health Ministry, which does not distinguish between combatant and civilian deaths, has cited so far in nearly two years of war? | AE7: 45860 | AF7: 45860 | AG7: 2025 | AH7: israel | AI7: jews | AJ7: hamas
A8: 7 | B8: 45846 | C8: Bret Stephens | D8: The New York Times | E8: For Israel, It Pays to Be a Winner | F8: A core misconception about Israelâ€™s policy since Oct. 7 is that the country has favored military action at the expense of diplomacy. The truth is that itâ€™s Israelâ€™s decisive battlefield victories that have created diplomatic openings that have been out of reach for decades â€” and would have remained so if Israel hadnâ€™t won. | G8: 0 | H8: 0 | I8: 0 | J8: 0 | K8: 0 | L8: 0 | M8: 1 | N8: 0 | O8: 0 | P8: 8 | Q8: 54 | R8: 0.686 | S8: 0.256 | T8: 0.256 | U8: 0.5 | V8: 0.5 | W8: 0.5 | X8: 0.256 | Y8: 0.5 | Z8: 0.5 | AA8: 0.5 | AB8: 0.5 | AC8: 0.471 | AD8: Title: For Israel, It Pays to Be a Winner. Title: For Israel, It Pays to Be a Winner. First Paragraph: A core misconception about Israelâ€™s policy since Oct. 7 is that the country has favored military action at the expense of diplomacy. The truth is that itâ€™s Israelâ€™s decisive battlefield victories that have created diplomatic openings that have been out of reach for decades â€” and would have remained so if Israel hadnâ€™t won. | AE8: 45846 | AF8: 45846 | AG8: 2025 | AH8: israel | AI8: jews | AJ8: hamas
A9: 8 | B9: 45839 | C9: Bret Stephens | D9: The New York Times | E9: What â€˜Globalize the Intifadaâ€™ Really Means | F9: Zohran Mamdani got three chances to repudiate the expression â€œglobalize the intifadaâ€ in a weekend interview with NBCâ€™s Kristen Welker. It would have been easy, and politically smart, for the Democratic candidate for New York mayor to say that heâ€™d been educated about the phraseâ€™s violent connotation and that he regretted not rejecting it sooner. Instead, he ducked each time, saying that although he does not use those words himself, he would decline to â€œpoliceâ€ the language of others. | G9: 0 | H9: 0 | I9: 0 | J9: 0 | K9: 0 | L9: 0 | M9: 1 | N9: 0 | O9: 0 | P9: 6 | Q9: 79 | R9: 0.286 | S9: 0.339 | T9: 0.339 | U9: 0.5 | V9: 0.5 | W9: 0.5 | X9: 0.5 | Y9: 0.5 | Z9: 0.5 | AA9: 0.5 | AB9: 0.5 | AC9: 0.3125 | AD9: Title: What â€˜Globalize the Intifadaâ€™ Really Means. Title: What â€˜Globalize the Intifadaâ€™ Really Means. First Paragraph: Zohran Mamdani got three chances to repudiate the expression â€œglobalize the intifadaâ€ in a weekend interview with NBCâ€™s Kristen Welker. It would have been easy, and politically smart, for the Democratic candidate for New York mayor to say that heâ€™d been educated about the phraseâ€™s violent connotation and that he regretted not rejecting it sooner. Instead, he ducked each time, saying that although he does not use those words himself, he would decline to â€œpoliceâ€ the language of others. | AE9: 45839 | AF9: 45839 | AG9: 2025 | AH9: israel | AI9: jews | AJ9: hamas
A10: 9 | B10: 45821 | C10: Bret Stephens | D10: The New York Times | E10: Israel Had the Courage to Do What Needed to Be Done | F10: It may be months or years before weâ€™ll know the full results of Israelâ€™s attack on Iranian nuclear and military targets, which began early Friday morning and could last for days or weeks. But critics of the strike â€” and already they are vocal â€” might at least ask themselves whether Israel had any realistic alternative against an adversary that has repeatedly vowed to wipe it off the map. | G10: 0 | H10: 0 | I10: 0 | J10: 0 | K10: 0 | L10: 0 | M10: 1 | N10: 0 | O10: 0 | P10: 11 | Q10: 69 | R10: 0.647 | S10: 0.157 | T10: 0.157 | U10: 0.5 | V10: 0.5 | W10: 0.5 | X10: 0.157 | Y10: 0.5 | Z10: 0.5 | AA10: 0.5 | AB10: 0.5 | AC10: 0.402 | AD10: Title: Israel Had the Courage to Do What Needed to Be Done. Title: Israel Had the Courage to Do What Needed to Be Done. First Paragraph: It may be months or years before weâ€™ll know the full results of Israelâ€™s attack on Iranian nuclear and military targets, which began early Friday morning and could last for days or weeks. But critics of the strike â€” and already they are vocal â€” might at least ask themselves whether Israel had any realistic alternative against an adversary that has repeatedly vowed to wipe it off the map. | AE10: 45821 | AF10: 45821 | AG10: 2025 | AH10: israel | AI10: jews | AJ10: hamas
A11: 10 | B11: 45748 | C11: Bret Stephens | D11: The New York Times | E11: Here Is the Real Route to Freeing Palestinians | F11: The world should remember the name of Odai Al-Rubai. The 22-year-old Palestinian man joined protests in Gaza last week to demand an end to 18 years of Hamasâ€™s violent misrule in the territory. Demonstrators could be heard shouting, â€œOut, out, Hamas, get outâ€ and â€œHamas are terrorists,â€ while displaying banners saying, â€œHamas does not represent us.â€ In retaliation, Al-Rubaiâ€™s family says, he was kidnapped, tortured and murdered by members of Hamasâ€™s Qassam Brigades. Then his body was dumped in front of the family home. | G11: 0 | H11: 0 | I11: 0 | J11: 0 | K11: 0 | L11: 0 | M11: 1 | N11: 0 | O11: 0 | P11: 8 | Q11: 84 | R11: 0.485 | S11: 0.285 | T11: 0.285 | U11: 0.5 | V11: 0.5 | W11: 0.079 | X11: 0.5 | Y11: 0.226 | Z11: 0.226 | AA11: 0.5 | AB11: 0.5 | AC11: 0.385 | AD11: Title: Here Is the Real Route to Freeing Palestinians. Title: Here Is the Real Route to Freeing Palestinians. First Paragraph: The world should remember the name of Odai Al-Rubai. The 22-year-old Palestinian man joined protests in Gaza last week to demand an end to 18 years of Hamasâ€™s violent misrule in the territory. Demonstrators could be heard shouting, â€œOut, out, Hamas, get outâ€ and â€œHamas are terrorists,â€ while displaying banners saying, â€œHamas does not represent us.â€ In retaliation, Al-Rubaiâ€™s family says, he was kidnapped, tortured and murdered by members of Hamasâ€™s Qassam Brigades. Then his body was dumped in front of the family home. | AE11: 45748 | AF11: 45748 | AG11: 2025 | AH11: israel | AI11: jews | AJ11: hamas
A12: 11 | B12: 45715 | C12: Bret Stephens | D12: The New York Times | E12: Earth to Barnard College: Enough | F12: The pro-Palestinian mob is back in Manhattanâ€™s Morningside Heights. So are the Hamas-friendly chants of â€œintifada revolutionâ€ and posts about â€œresistance until return.â€ So is the bullying and violence. | G12: 0 | H12: 0 | I12: 0 | J12: 0 | K12: 0 | L12: 0 | M12: 1 | N12: 0 | O12: 0 | P12: 5 | Q12: 29 | R12: 0.489 | S12: 0.065 | T12: 0.065 | U12: 0.5 | V12: 0.5 | W12: 0.046 | X12: 0.5 | Y12: 0.289 | Z12: 0.5 | AA12: 0.5 | AB12: 0.5 | AC12: 0.277 | AD12: Title: Earth to Barnard College: Enough. Title: Earth to Barnard College: Enough. First Paragraph: The pro-Palestinian mob is back in Manhattanâ€™s Morningside Heights. So are the Hamas-friendly chants of â€œintifada revolutionâ€ and posts about â€œresistance until return.â€ So is the bullying and violence. | AE12: 45715 | AF12: 45715 | AG12: 2025 | AH12: israel | AI12: jews | AJ12: hamas
A13: 12 | B13: 45699 | C13: Bret Stephens | D13: The New York Times | E13: The Horror Show of Hamas Must End Now | F13: On Saturday, Hamas gunmen paraded three skeletally thin Israeli hostages for a propaganda video in which they were forced to thank their captors before their handover to the Red Cross. One of the hostages, Eli Sharabi, returned to Israel to learn that his wife, Lianne, and their teenage daughters, Noiya and Yahel, had been murdered on Oct. 7. | G13: 0 | H13: 0 | I13: 0 | J13: 0 | K13: 0 | L13: 0 | M13: 1 | N13: 0 | O13: 0 | P13: 8 | Q13: 58 | R13: 0.052 | S13: 0.135 | T13: 0.135 | U13: 0.5 | V13: 0.5 | W13: 0.156 | X13: 0.095 | Y13: 0.5 | Z13: 0.5 | AA13: 0.5 | AB13: 0.5 | AC13: 0.0935 | AD13: Title: The Horror Show of Hamas Must End Now. Title: The Horror Show of Hamas Must End Now. First Paragraph: On Saturday, Hamas gunmen paraded three skeletally thin Israeli hostages for a propaganda video in which they were forced to thank their captors before their handover to the Red Cross. One of the hostages, Eli Sharabi, returned to Israel to learn that his wife, Lianne, and their teenage daughters, Noiya and Yahel, had been murdered on Oct. 7. | AE13: 45699 | AF13: 45699 | AG13: 2025 | AH13: israel | AI13: jews | AJ13: hamas
... A84: 83 | B84: 45947 | C84: Isabel Kershner | D84: The New York Times | E84: After â€˜Horrors,â€™ Israeli Hostages Taste Freedom and Savor Family Reunions | F84: Some former captives have been sent home from the hospital. But a doctor said they all had â€œendured untold adversity,â€ as details emerge of their time in Gazaâ€™s tunnels. Eitan Horn, a freed hostage in his late 30s, lost about half his body weight and was forced to walk for about 12 hours through the tunnels beneath Gaza when his captors wanted to move him, his sister-in-law, Dalia Cusnir, said in an interview. | G84: 0 | H84: 0 | I84: 0 | J84: 0 | K84: 0 | L84: 0 | M84: 0 | N84: 0 | O84: 0 | P84: 10 | Q84: 73 | R84: 0.498 | S84: 0.288 | T84: 0.288 | U84: 0.5 | V84: 0.5 | W84: 0.5 | X84: 0.5 | Y84: 0.5 | Z84: 0.252 | AA84: 0.5 | AB84: 0.5 | AC84: 0.393 | AD84: Title: After â€˜Horrors,â€™ Israeli Hostages Taste Freedom and Savor Family Reunions. Title: After â€˜Horrors,â€™ Israeli Hostages Taste Freedom and Savor Family Reunions. First Paragraph: Some former captives have been sent home from the hospital. But a doctor said they all had â€œendured untold adversity,â€ as details emerge of their time in Gazaâ€™s tunnels. Eitan Horn, a freed hostage in his late 30s, lost about half his body weight and was forced to walk for about 12 hours through the tunnels beneath Gaza when his captors wanted to move him, his sister-in-law, Dalia Cusnir, said in an interview. | AE84: 45947 | AF84: 45947 | AG84: 2025 | AH84: israeli | AI84: israel | AJ84: gaza
A85: 84 | B85: 45947 | C85: John Yoon | D85: The New York Times | E85: U.S. Says Louisiana Man Joined Hamas-Led 2023 Attack on Israel | F85: The man appeared in court on Friday morning, after federal prosecutors accused him of joining Gazan militants in attacking Israel and lying to obtain a U.S. visa. Federal prosecutors in Louisiana accused a man of participating in the Hamas-led October 2023 attack on Israel and then traveling to the United States on a fraudulent visa, according to a criminal complaint unsealed this week. | G85: 0 | H85: 0 | I85: 0 | J85: 0 | K85: 0 | L85: 0 | M85: 0 | N85: 0 | O85: 0 | P85: 10 | Q85: 63 | R85: 0.186 | S85: 0.194 | T85: 0.194 | U85: 0.5 | V85: 0.5 | W85: 0.18 | X85: 0.194 | Y85: 0.5 | Z85: 0.5 | AA85: 0.5 | AB85: 0.5 | AC85: 0.19 | AD85: Title: U.S. Says Louisiana Man Joined Hamas-Led 2023 Attack on Israel. Title: U.S. Says Louisiana Man Joined Hamas-Led 2023 Attack on Israel. First Paragraph: The man appeared in court on Friday morning, after federal prosecutors accused him of joining Gazan militants in attacking Israel and lying to obtain a U.S. visa. Federal prosecutors in Louisiana accused a man of participating in the Hamas-led October 2023 attack on Israel and then traveling to the United States on a fraudulent visa, according to a criminal complaint unsealed this week. | AE85: 45947 | AF85: 45947 | AG85: 2025 | AH85: hamas led | AI85: 2023 attack | AJ85: 2023
A86: 85 | B86: 45947 | C86: Ezra Klein | D86: The New York Times | E86: Two Middle East Negotiators Assess Trumpâ€™s Israel-Hamas Deal | F86: On Oct. 9, the Israeli government voted to ratify an agreement between Israel and Hamas brokered by the Trump administration, Qatar and Turkey that, it is hoped, finally brings an end to the conflict. This deal has already led to the release of the remaining 20 Israeli hostages. Their coming home was an incredibly emotional thing to watch. | G86: 0 | H86: 0 | I86: 0 | J86: 0 | K86: 0 | L86: 0 | M86: 1 | N86: 0 | O86: 0 | P86: 8 | Q86: 58 | R86: 0.493 | S86: 0.83 | T86: 0.83 | U86: 0.5 | V86: 0.5 | W86: 0.67 | X86: 0.67 | Y86: 0.5 | Z86: 0.5 | AA86: 0.5 | AB86: 0.67 | AC86: 0.6615 | AD86: Title: Two Middle East Negotiators Assess Trumpâ€™s Israel-Hamas Deal. Title: Two Middle East Negotiators Assess Trumpâ€™s Israel-Hamas Deal. First Paragraph: On Oct. 9, the Israeli government voted to ratify an agreement between Israel and Hamas brokered by the Trump administration, Qatar and Turkey that, it is hoped, finally brings an end to the conflict. This deal has already led to the release of the remaining 20 Israeli hostages. Their coming home was an incredibly emotional thing to watch. | AE86: 45947 | AF86: 45947 | AG86: 2025 | AH86: negotiators | AI86: trump | AJ86: deal
A87: 86 | B87: 45947 | C87: Dana Stroul | D87: The New York Times | E87: The Real Trump Factor in the Gaza Deal | F87: Praise for President Trumpâ€™s diplomacy in brokering a cease-fire in Gaza has mostly focused on how he persuaded Prime Minister Benjamin Netanyahu of Israel to accept a deal. Many assume that Mr. Trump threatened to withdraw U.S. support from Israel or otherwise pressured the Israeli leader into capitulating. But there is a more convincing explanation for Mr. Trumpâ€™s success. Far from merely menacing Mr. Netanyahu with consequences, the American presidentâ€™s key intervention was to give a political lifeline to the deeply unpopular Israeli leader. The secret of Mr. Trumpâ€™s success with Mr. Netanyahu was offering carrots on domestic politics, not sticks on foreign policy. | G87: 0 | H87: 0 | I87: 0 | J87: 0 | K87: 0 | L87: 0 | M87: 1 | N87: 0 | O87: 0 | P87: 8 | Q87: 104 | R87: 0.392 | S87: 0.773 | T87: 0.465 | U87: 0.824 | V87: 0.5 | W87: 0.5 | X87: 0.735 | Y87: 0.5 | Z87: 0.91 | AA87: 0.5 | AB87: 0.793 | AC87: 0.5825 | AD87: Title: The Real Trump Factor in the Gaza Deal. Title: The Real Trump Factor in the Gaza Deal. First Paragraph: Praise for President Trumpâ€™s diplomacy in brokering a cease-fire in Gaza has mostly focused on how he persuaded Prime Minister Benjamin Netanyahu of Israel to accept a deal. Many assume that Mr. Trump threatened to withdraw U.S. support from Israel or otherwise pressured the Israeli leader into capitulating. But there is a more convincing explanation for Mr. Trumpâ€™s success. Far from merely menacing Mr. Netanyahu with consequences, the American presidentâ€™s key intervention was to give a political lifeline to the deeply unpopular Israeli leader. The secret of Mr. Trumpâ€™s success with Mr. Netanyahu was offering carrots on domestic politics, not sticks on foreign policy. | AE87: 45947 | AF87: 45947 | AG87: 2025 | AH87: trump | AI87: factor | AJ87: success
A88: 87 | B88: 45946 | C88: Emma Fitzsimmons | D88: The New York Times | E88: Mamdani Faces Vitriolic Attacks After Comments About Hamas | F88: Zohran Mamdani, the front-runner in the race for mayor of New York City, was criticized by lawmakers from both parties after he dodged a question about Hamasâ€™s future. His campaign denounced the attacks as Islamophobic. Zohran Mamdani, the Democratic nominee for mayor of New York City, faced vitriolic attacks that suggested he was a terrorist sympathizer after he gave an indirect answer to a question on Wednesday about whether Hamas should lay down arms and step aside in Gaza. President Trump said on Thursday that if Hamas continued to kill people in Gaza, â€œwe will have no choice but to go in and kill them,â€ a stark warning after Hamas fighters were captured on video in recent days executing members of rival groups in the Palestinian territory. | G88: 0 | H88: 0 | I88: 0 | J88: 0 | K88: 1 | L88: 0 | M88: 0 | N88: 0 | O88: 0 | P88: 8 | Q88: 127 | R88: 0.129 | S88: 0.134 | T88: 0.134 | U88: 0.5 | V88: 0.5 | W88: 0.141 | X88: 0.5 | Y88: 0.101 | Z88: 0.113 | AA88: 0.5 | AB88: 0.101 | AC88: 0.1315 | AD88: Title: Mamdani Faces Vitriolic Attacks After Comments About Hamas. Title: Mamdani Faces Vitriolic Attacks After Comments About Hamas. First Paragraph: Zohran Mamdani, the front-runner in the race for mayor of New York City, was criticized by lawmakers from both parties after he dodged a question about Hamasâ€™s future. His campaign denounced the attacks as Islamophobic. Zohran Mamdani, the Democratic nominee for mayor of New York City, faced vitriolic attacks that suggested he was a terrorist sympathizer after he gave an indirect answer to a question on Wednesday about whether Hamas should lay down arms and step aside in Gaza. President Trump said on Thursday that if Hamas continued to kill people in Gaza, â€œwe will have no choice but to go in and kill them,â€ a stark warning after Hamas fighters were captured on video in recent days executing members of rival groups in the Palestinian territory. | AE88: 45946 | AF88: 45946 | AG88: 2025 | AH88: attacks | AI88: question | AJ88: comments
A89: 88 | B89: 45946 | C89: Zolan Kanno-Youngs | D89: The New York Times | E89: Trump Warns Hamas of Strikes if Violence in Gaza Continues | F89: The president later clarified that the United States would not be involved in such an action. President Trump said on Thursday that if Hamas continued to kill people in Gaza, â€œwe will have no choice but to go in and kill them,â€ a stark warning after Hamas fighters were captured on video in recent days executing members of rival groups in the Palestinian territory. | G89: 0 | H89: 0 | I89: 0 | J89: 0 | K89: 0 | L89: 1 | M89: 0 | N89: 0 | O89: 0 | P89: 10 | Q89: 64 | R89: 0.114 | S89: 0.246 | T89: 0.246 | U89: 0.5 | V89: 0.5 | W89: 0.101 | X89: 0.5 | Y89: 0.101 | Z89: 0.101 | AA89: 0.5 | AB89: 0.101 | AC89: 0.18 | AD89: Title: Trump Warns Hamas of Strikes if Violence in Gaza Continues. Title: Trump Warns Hamas of Strikes if Violence in Gaza Continues. First Paragraph: The president later clarified that the United States would not be involved in such an action. President Trump said on Thursday that if Hamas continued to kill people in Gaza, â€œwe will have no choice but to go in and kill them,â€ a stark warning after Hamas fighters were captured on video in recent days executing members of rival groups in the Palestinian territory. | AE89: 45946 | AF89: 45946 | AG89: 2025 | AH89: warns | AI89: trump | AJ89: kill
A90: 89 | B90: 45946 | C90: Jonathan Wolfe | D90: The New York Times | E90: Hacked Airport P.A. Systems Broadcast Anti-Trump and Pro-Hamas Messages | F90: The hacks at four North American airports raised fresh concerns over the security of noncritical but highly visible airport infrastructure. The airports said the disruption was minimal. The public address systems at four airports in North America were hacked on Tuesday and used to broadcast messages praising Hamas and criticizing President Trump, officials said. | G90: 0 | H90: 0 | I90: 0 | J90: 0 | K90: 1 | L90: 0 | M90: 0 | N90: 0 | O90: 0 | P90: 9 | Q90: 54 | R90: 0.243 | S90: 0.22 | T90: 0.22 | U90: 0.5 | V90: 0.5 | W90: 0.233 | X90: 0.5 | Y90: 0.5 | Z90: 0.5 | AA90: 0.5 | AB90: 0.233 | AC90: 0.2315 | AD90: Title: Hacked Airport P.A. Systems Broadcast Anti-Trump and Pro-Hamas Messages. Title: Hacked Airport P.A. Systems Broadcast Anti-Trump and Pro-Hamas Messages. First Paragraph: The hacks at four North American airports raised fresh concerns over the security of noncritical but highly visible airport infrastructure. The airports said the disruption was minimal. The public address systems at four airports in North America were hacked on Tuesday and used to broadcast messages praising Hamas and criticizing President Trump, officials said. | AE90: 45946 | AF90: 45946 | AG90: 2025 | AH90: airport | AI90: systems | AJ90: broadcast
A91: 90 | B91: 45946 | C91: Shuaib Almosawa | D91: The New York Times | E91: Yemenâ€™s Houthis Confirm Killing of Top Military Official | F91: It was unclear when Maj. Gen. Mohammed al-Ghomari was killed, or by whom, but Israel appeared to claim the killing. The Houthi militia in Yemen said on Thursday that a senior military official had been killed, in what it described as an â€œIsraeli-Americanâ€ airstrike, without disclosing when. | G91: 0 | H91: 0 | I91: 0 | J91: 0 | K91: 0 | L91: 0 | M91: 0 | N91: 0 | O91: 0 | P91: 8 | Q91: 47 | R91: 0.119 | S91: 0.228 | T91: 0.228 | U91: 0.5 | V91: 0.5 | W91: 0.5 | X91: 0.28 | Y91: 0.5 | Z91: 0.5 | AA91: 0.5 | AB91: 0.5 | AC91: 0.1735 | AD91: Title: Yemenâ€™s Houthis Confirm Killing of Top Military Official. Title: Yemenâ€™s Houthis Confirm Killing of Top Military Official. First Paragraph: It was unclear when Maj. Gen. Mohammed al-Ghomari was killed, or by whom, but Israel appeared to claim the killing. The Houthi militia in Yemen said on Thursday that a senior military official had been killed, in what it described as an â€œIsraeli-Americanâ€ airstrike, without disclosing when. | AE91: 45946 | AF91: 45946 | AG91: 2025 | AH91: yemen | AI91: top military | AJ91: confirm
A92: 91 | B92: 45946 | C92: Ephrat Livni | D92: The New York Times | E92: Where Does the Israel-Hamas Cease-Fire Stand? | F92: Unresolved issues and flare-ups of violence threaten to destabilize the fragile agreement. The cease-fire between Israel and Hamas has held for more than a week. But each side has accused the other of violating the agreement, which rests on shaky ground, and there are unresolved issues that put the future of the truce at risk. | G92: 0 | H92: 0 | I92: 0 | J92: 0 | K92: 0 | L92: 0 | M92: 0 | N92: 0 | O92: 0 | P92: 6 | Q92: 55 | R92: 0.437 | S92: 0.085 | T92: 0.085 | U92: 0.5 | V92: 0.5 | W92: 0.212 | X92: 0.212 | Y92: 0.5 | Z92: 0.5 | AA92: 0.5 | AB92: 0.5 | AC92: 0.261 | AD92: Title: Where Does the Israel-Hamas Cease-Fire Stand?. Title: Where Does the Israel-Hamas Cease-Fire Stand?. First Paragraph: Unresolved issues and flare-ups of violence threaten to destabilize the fragile agreement. The cease-fire between Israel and Hamas has held for more than a week. But each side has accused the other of violating the agreement, which rests on shaky ground, and there are unresolved issues that put the future of the truce at risk. | AE92: 45946 | AF92: 45946 | AG92: 2025 | AH92: role | AI92: red cross | AJ92: video
A93: 92 | B93: 45946 | C93: Natan Odenheimer | D93: The New York Times | E93: A Day of Somber Ceremony in Israel, With a Fragile Cease-Fire Holding | F93: Ceremonies took place on Thursday to commemorate two years since the surprise attack of Oct. 7, 2023, on southern Israel. Israel marked a national day of commemoration on Thursday for the victims of the Hamas-led Oct. 7, 2023, attack on southern Israel, and for those who died in the ensuing war, almost a week after a cease-fire in Gaza was declared. | G93: 0 | H93: 0 | I93: 0 | J93: 0 | K93: 0 | L93: 0 | M93: 0 | N93: 0 | O93: 0 | P93: 12 | Q93: 61 | R93: 0.441 | S93: 0.595 | T93: 0.595 | U93: 0.5 | V93: 0.5 | W93: 0.423 | X93: 0.595 | Y93: 0.5 | Z93: 0.423 | AA93: 0.5 | AB93: 0.5 | AC93: 0.518 | AD93: Title: A Day of Somber Ceremony in Israel, With a Fragile Cease-Fire Holding. Title: A Day of Somber Ceremony in Israel, With a Fragile Cease-Fire Holding. First Paragraph: Ceremonies took place on Thursday to commemorate two years since the surprise attack of Oct. 7, 2023, on southern Israel. Israel marked a national day of commemoration on Thursday for the victims of the Hamas-led Oct. 7, 2023, attack on southern Israel, and for those who died in the ensuing war, almost a week after a cease-fire in Gaza was declared. | AE93: 45946 | AF93: 45946 | AG93: 2025 | AH93: cease fire | AI93: cease | AJ93: fire
A94: 93 | B94: 45946 | C94: M. Gessen | D94: The New York Times | E94: Her Optimism Has Won Her Some of the Most Powerful Enemies in the World | F94: Albanese became a hometown hero after the White House branded her an enemy, which it did because of her work, over the past three years, as the United Nations special rapporteur for the occupied Palestinian territories. In the course of that work, she has pursued strategies that are as legally ambitious as they are politically risky. She has documented human rights abuses, as her predecessors did. She infuriated some of her allies by condemning the Hamas violence of Oct. 7, 2023, then caused a storm when she leaped onto social media to contest a boilerplate statement by the president of France that framed the violence as antisemitic. Perhaps most explosively, she has called out the corporations, including some of the largest in the United States, that enable and benefit from human rights abuses, and which are likely to continue to do so, regardless of the cease-fire. | G94: 0 | H94: 0 | I94: 0 | J94: 0 | K94: 0 | L94: 0 | M94: 1 | N94: 0 | O94: 0 | P94: 14 | Q94: 146 | R94: 0.884 | S94: 0.396 | T94: 0.293 | U94: 0.5 | V94: 0.5 | W94: 0.06 | X94: 0.5 | Y94: 0.522 | Z94: 0.5 | AA94: 0.5 | AB94: 0.5 | AC94: 0.64 | AD94: Title: Her Optimism Has Won Her Some of the Most Powerful Enemies in the World. Title: Her Optimism Has Won Her Some of the Most Powerful Enemies in the World. First Paragraph: Albanese became a hometown hero after the White House branded her an enemy, which it did because of her work, over the past three years, as the United Nations special rapporteur for the occupied Palestinian territories. In the course of that work, she has pursued strategies that are as legally ambitious as they are politically risky. She has documented human rights abuses, as her predecessors did. She infuriated some of her allies by condemning the Hamas violence of Oct. 7, 2023, then caused a storm when she leaped onto social media to contest a boilerplate statement by the president of France that framed the violence as antisemitic. Perhaps most explosively, she has called out the corporations, including some of the largest in the United States, that enable and benefit from human rights abuses, and which are likely to continue to do so, regardless of the cease-fire. | AE94: 45946 | AF94: 45946 | AG94: 2025 | AH94: abuses | AI94: enemies | AJ94: won
A95: 94 | B95: 45945 | C95: Nicholas Kristoff | D95: The New York Times | E95: What Lies Ahead in the Middle East Isnâ€™t Right vs. Wrong. Itâ€™s Right vs. Right. | F95: My keyboard, so used to criticisms of President Trump, is shocked as I hammer out this column. But Trump genuinely deserves great credit for (belatedly) ramming through the Gaza cease-fire and release of hostages and detainees. Bravo, Mr. President. Yet what lies ahead is more prayer than plan, and to make this a lasting peace it would help if we all discarded the Manichaean paradigm of good versus evil that many Westerners apply to Israelis and Palestinians (while disagreeing on who gets which label), making compromise difficult or impossible. To make progress, it may help to think of the conflict not in terms of right versus wrong, but of right versus right. | G95: 1 | H95: 0 | I95: 0 | J95: 0 | K95: 0 | L95: 0 | M95: 1 | N95: 0 | O95: 1 | P95: 15 | Q95: 112 | R95: 0.272 | S95: 0.77 | T95: 0.938 | U95: 0.5 | V95: 0.5 | W95: 0.5 | X95: 0.5 | Y95: 0.5 | Z95: 0.751 | AA95: 0.5 | AB95: 0.549 | AC95: 0.521 | AD95: Title: What Lies Ahead in the Middle East Isnâ€™t Right vs. Wrong. Itâ€™s Right vs. Right.. Title: What Lies Ahead in the Middle East Isnâ€™t Right vs. Wrong. Itâ€™s Right vs. Right.. First Paragraph: My keyboard, so used to criticisms of President Trump, is shocked as I hammer out this column. But Trump genuinely deserves great credit for (belatedly) ramming through the Gaza cease-fire and release of hostages and detainees. Bravo, Mr. President. Yet what lies ahead is more prayer than plan, and to make this a lasting peace it would help if we all discarded the Manichaean paradigm of good versus evil that many Westerners apply to Israelis and Palestinians (while disagreeing on who gets which label), making compromise difficult or impossible. To make progress, it may help to think of the conflict not in terms of right versus wrong, but of right versus right. | AE95: 45945 | AF95: 45945 | AG95: 2025 | AH95: right | AI95: lies | AJ95: wrong
A96: 95 | B96: 45945 | C96: Ephrat Livni | D96: The New York Times | E96: Hamas Says It Has Returned All Hostage Remains It Can Recover | F96: The militants said they would need special equipment to retrieve more bodies in Gaza. The announcement could put the truce with Israel at risk. Hamasâ€™s military wing, the Qassam Brigades, said on Wednesday night that it had handed over all of the remains of Israeli hostages that it had been able to recover without additional equipment, potentially putting a cease-fire with Israel in the Gaza Strip at risk. | G96: 1 | H96: 0 | I96: 0 | J96: 0 | K96: 0 | L96: 0 | M96: 0 | N96: 0 | O96: 1 | P96: 11 | Q96: 68 | R96: 0.576 | S96: 0.161 | T96: 0.161 | U96: 0.5 | V96: 0.5 | W96: 0.286 | X96: 0.171 | Y96: 0.5 | Z96: 0.218 | AA96: 0.5 | AB96: 0.5 | AC96: 0.3685 | AD96: Title: Hamas Says It Has Returned All Hostage Remains It Can Recover. Title: Hamas Says It Has Returned All Hostage Remains It Can Recover. First Paragraph: The militants said they would need special equipment to retrieve more bodies in Gaza. The announcement could put the truce with Israel at risk. Hamasâ€™s military wing, the Qassam Brigades, said on Wednesday night that it had handed over all of the remains of Israeli hostages that it had been able to recover without additional equipment, potentially putting a cease-fire with Israel in the Gaza Strip at risk. | AE96: 45945 | AF96: 45945 | AG96: 2025 | AH96: role | AI96: red cross | AJ96: video
A97: 96 | B97: 45945 | C97: Andrew Ross | D97: The New York Times | E97: The Israel-Gaza War Always Had an Unacknowledged Third Front | F97: Nothing can undo the staggering loss of life and the bloodshed of the attacks of Oct. 7, 2023, the relentless bombardment and starvation of Gazans and the increasing violence directed against West Bank communities. But amid the prospects of a lasting cease-fire and Palestinian self-determination, there must also be pressure to end the unsparing detention of the thousands of Palestinians who continue to be held in Israelâ€™s prisons, many under conditions that defy international laws mandating humane treatment of detainees. | G97: 0 | H97: 0 | I97: 0 | J97: 0 | K97: 0 | L97: 0 | M97: 1 | N97: 0 | O97: 0 | P97: 9 | Q97: 80 | R97: 0.245 | S97: 0.101 | T97: 0.101 | U97: 0.5 | V97: 0.5 | W97: 0.5 | X97: 0.419 | Y97: 0.419 | Z97: 0.5 | AA97: 0.5 | AB97: 0.5 | AC97: 0.173 | AD97: Title: The Israel-Gaza War Always Had an Unacknowledged Third Front. Title: The Israel-Gaza War Always Had an Unacknowledged Third Front. First Paragraph: Nothing can undo the staggering loss of life and the bloodshed of the attacks of Oct. 7, 2023, the relentless bombardment and starvation of Gazans and the increasing violence directed against West Bank communities. But amid the prospects of a lasting cease-fire and Palestinian self-determination, there must also be pressure to end the unsparing detention of the thousands of Palestinians who continue to be held in Israelâ€™s prisons, many under conditions that defy international laws mandating humane treatment of detainees. | AE97: 45945 | AF97: 45945 | AG97: 2025 | AH97: israel gaza war | AI97: always | AJ97: third
... A201: 200 | B201: 45236 | C201: Nick Cumming-Bruce | D201: The New York Times | E201: U.N. Says Israel-Gaza War Is Deadliest Ever for Its Personnel | F201: The U.N. secretary general, AntÃ³nio Guterres, said Monday that 89 employees of UNRWA, its agency aiding Palestinian refugees, had been killed since the war began. The United Nations secretary general, AntÃ³nio Guterres, said on Monday that 89 employees of the U.N. agency aiding Palestinian refugees, known as UNRWA, had been killed in Gaza in the month of war between Israel and Hamas. That is more â€œthan in any comparable period in the history of our organization,â€ he told reporters at U.N. headquarters in New York, adding that many of the employees had been killed with members of their family. The United Nations employs large numbers of Palestinians in Gaza, where almost half the working-age population is unemployed. On Sunday, the leaders of United Nations agencies and other humanitarian groups issued a joint statement calling for an immediate cease-fire, saying, â€œEnough is enough. This must stop now.â€ In the statement, they expressed â€œshock and horrorâ€ at the loss of life and called for the immediate release of hostages taken during the Hamas attacks in Israel last month. They noted that â€œmore than 100 attacks against health careâ€ had been reported and that â€œscores of aid workersâ€ had been killed since the attacks and Israelâ€™s retaliatory airstrikes on Gaza. Of the loss of U.N. staff members, Juliette Touma, a spokeswoman for UNRWA, said: â€œThe number goes up every day.â€ â€œThey are killed in the north, the middle and the south, men and women, some at home, some at displacement shelters, some bringing refugees to the shelters,â€ she added. One staff member was killed as he waited in line for bread, she said, and another was killed at home with his wife and eight children. Most worked in the agencyâ€™s schools in Gaza, she said. The World Health Organization said 16 health care workers had died while on duty in Gaza, and the International Federation of Red Cross and Red Crescent Societies said its member organizations had lost seven staff members in the war. The fatalities, the International Federation of Red Cross and Red Crescent Societies said, included three medical staff of Magen David Adom, Israelâ€™s emergency medical service, who were killed as they tried to rescue people from the kibbutzim under attack by Hamas and take them to the hospital. | G201: 0 | H201: 0 | I201: 0 | J201: 0 | K201: 0 | L201: 1 | M201: 0 | N201: 0 | O201: 0 | P201: 10 | Q201: 378 | R201: 0.079 | S201: 0.184 | T201: 0.097 | U201: 0.5 | V201: 0.5 | W201: 0.098 | X201: 0.089 | Y201: 0.163 | Z201: 0.11 | AA201: 0.5 | AB201: 0.5 | AC201: 0.1315 | AD201: Title: U.N. Says Israel-Gaza War Is Deadliest Ever for Its Personnel. Title: U.N. Says Israel-Gaza War Is Deadliest Ever for Its Personnel. First Paragraph: The U.N. secretary general, AntÃ³nio Guterres, said Monday that 89 employees of UNRWA, its agency aiding Palestinian refugees, had been killed since the war began. The United Nations secretary general, AntÃ³nio Guterres, said on Monday that 89 employees of the U.N. agency aiding Palestinian refugees, known as UNRWA, had been killed in Gaza in the month of war between Israel and Hamas. That is more â€œthan in any comparable period in the history of our organization,â€ he told reporters at U.N. headquarters in New York, adding that many of the employees had been killed with members of their family. The United Nations employs large numbers of Palestinians in Gaza, where almost half the working-age population is unemployed. On Sunday, the leaders of United Nations agencies and other humanitarian groups issued a joint statement calling for an immediate cease-fire, saying, â€œEnough is enough. This must stop now.â€ In the statement, they expressed â€œshock and horrorâ€ at the loss of life and called for the immediate release of hostages taken during the Hamas attacks in Israel last month. They noted that â€œmore than 100 attacks against health careâ€ had been reported and that â€œscores of aid workersâ€ had been killed since the attacks and Israelâ€™s retaliatory airstrikes on Gaza. Of the loss of U.N. staff members, Juliette Touma, a spokeswoman for UNRWA, said: â€œThe number goes up every day.â€ â€œThey are killed in the north, the middle and the south, men and women, some at home, some at displacement shelters, some bringing refugees to the shelters,â€ she added. One staff member was killed as he waited in line for bread, she said, and another was killed at home with his wife and eight children. Most worked in the agencyâ€™s schools in Gaza, she said. The World Health Organization said 16 health care workers had died while on duty in Gaza, and the International Federation of Red Cross and Red Crescent Societies said its member organizations had lost seven staff members in the war. The fatalities, the International Federation of Red Cross and Red Crescent Societies said, included three medical staff of Magen David Adom, Israelâ€™s emergency medical service, who were killed as they tried to rescue people from the kibbutzim under attack by Hamas and take them to the hospital. | AE201: 45236 | AF201: 45236 | AG201: 2023 | AH201: killed | AI201: staff | AJ201: refugees
A202: 201 | B202: 45234 | C202: Lisa Lerer | D202: The New York Times | E202: Obama Urges Americans to Take in â€˜Whole Truthâ€™ of Israel-Gaza War | F202: The former president said everyone was â€œcomplicit to some degreeâ€ in the current bloodshed and acknowledged the points of view on both sides of the conflict. Barack Obama offered a complex analysis of the conflict between Israel and Gaza, telling thousands of former aides that they were all â€œcomplicit to some degreeâ€ in the current bloodshed. â€œI look at this, and I think back, â€˜What could I have done during my presidency to move this forward, as hard as I tried?â€™â€ he said in an interview conducted by his former staffers for their podcast, Pod Save America. â€œBut thereâ€™s a part of me thatâ€™s still saying, â€˜Well, was there something else I could have done?â€™â€ Mr. Obama entered the White House convinced he could be the president who would resolve the decades-old conflict between Israelis and Palestinians. He left office after years of friction and mistrust with Prime Minister Benjamin Netanyahu of Israel, who was frustrated by the presidentâ€™s masterminding of the Iran nuclear deal and by his demands that Israel suspend new settlements. In his comments on Friday, delivered at a gathering of his former staff in Chicago, Mr. Obama acknowledged the strong emotions the war had raised, saying that â€œthis is century-old stuff thatâ€™s coming to the fore.â€ He blamed social media for amplifying the divisions and reducing a thorny international dispute to what he viewed as sloganeering. Yet he urged his former aides to â€œtake in the whole truth,â€ seemingly attempting to strike a balance between the killings on both sides. â€œWhat Hamas did was horrific, and thereâ€™s no justification for it,â€ Mr. Obama said. â€œAnd what is also true is that the occupation and whatâ€™s happening to Palestinians is unbearable.â€ He continued: â€œAnd what is also true is that there is a history of the Jewish people that may be dismissed unless your grandparents or your great-grandparents, or your uncle or your aunt tell you stories about the madness of antisemitism. And what is true is that there are people right now who are dying, who have nothing to do with what Hamas did.â€ Still, Mr. Obama appeared to acknowledge the limits of his musings about bridging divides and embracing complexity. â€œEven what I just said, which sounds very persuasive, still doesnâ€™t answer the fact of, all right, how do we prevent kids from being killed today?â€ he said. â€œBut the problem is that if you are dug in on that, well, the other side is dug in remembering the videos that Hamas took or what they did on the 7th, and theyâ€™re dug in, too, which means we will not stop those kids from dying.â€ | G202: 1 | H202: 0 | I202: 1 | J202: 0 | K202: 0 | L202: 1 | M202: 0 | N202: 1 | O202: 1 | P202: 11 | Q202: 440 | R202: 0.505 | S202: 0.412 | T202: 0.164 | U202: 0.182 | V202: 0.5 | W202: 0.112 | X202: 0.243 | Y202: 0.5 | Z202: 0.299 | AA202: 0.5 | AB202: 0.5 | AC202: 0.4585 | AD202: Title: Obama Urges Americans to Take in â€˜Whole Truthâ€™ of Israel-Gaza War. Title: Obama Urges Americans to Take in â€˜Whole Truthâ€™ of Israel-Gaza War. First Paragraph: The former president said everyone was â€œcomplicit to some degreeâ€ in the current bloodshed and acknowledged the points of view on both sides of the conflict. Barack Obama offered a complex analysis of the conflict between Israel and Gaza, telling thousands of former aides that they were all â€œcomplicit to some degreeâ€ in the current bloodshed. â€œI look at this, and I think back, â€˜What could I have done during my presidency to move this forward, as hard as I tried?â€™â€ he said in an interview conducted by his former staffers for their podcast, Pod Save America. â€œBut thereâ€™s a part of me thatâ€™s still saying, â€˜Well, was there something else I could have done?â€™â€ Mr. Obama entered the White House convinced he could be the president who would resolve the decades-old conflict between Israelis and Palestinians. He left office after years of friction and mistrust with Prime Minister Benjamin Netanyahu of Israel, who was frustrated by the presidentâ€™s masterminding of the Iran nuclear deal and by his demands that Israel suspend new settlements. In his comments on Friday, delivered at a gathering of his former staff in Chicago, Mr. Obama acknowledged the strong emotions the war had raised, saying that â€œthis is century-old stuff thatâ€™s coming to the fore.â€ He blamed social media for amplifying the divisions and reducing a thorny international dispute to what he viewed as sloganeering. Yet he urged his former aides to â€œtake in the whole truth,â€ seemingly attempting to strike a balance between the killings on both sides. â€œWhat Hamas did was horrific, and thereâ€™s no justification for it,â€ Mr. Obama said. â€œAnd what is also true is that the occupation and whatâ€™s happening to Palestinians is unbearable.â€ He continued: â€œAnd what is also true is that there is a history of the Jewish people that may be dismissed unless your grandparents or your great-grandparents, or your uncle or your aunt tell you stories about the madness of antisemitism. And what is true is that there are people right now who are dying, who have nothing to do with what Hamas did.â€ Still, Mr. Obama appeared to acknowledge the limits of his musings about bridging divides and embracing complexity. â€œEven what I just said, which sounds very persuasive, still doesnâ€™t answer the fact of, all right, how do we prevent kids from being killed today?â€ he said. â€œBut the problem is that if you are dug in on that, well, the other side is dug in remembering the videos that Hamas took or what they did on the 7th, and theyâ€™re dug in, too, which means we will not stop those kids from dying.â€ | AE202: 45234 | AF202: 45234 | AG202: 2023 | AH202: former | AI202: truth | AJ202: TRUE
A203: 202 | B203: 45238 | C203: Eric Schmitt | D203: The New York Times | E203: U.S. Strikes Iran-Linked Facility in Syria in Round of Retaliation | F203: Drone and rocket attacks on U.S. forces have continued in recent weeks, prompting a second round of retaliatory airstrikes in eastern Syria. For the second time in nearly two weeks, the United States carried out airstrikes against a facility used by Iranâ€™s Islamic Revolutionary Guards Corps and its proxies in eastern Syria early Thursday, ratcheting up retaliation for a steady stream of rocket and drone attacks against American forces in Iraq and Syria. The strikes by two Air Force F-15E jets against a weapons warehouse in Deir al Zour Province, Syria, came after U.S. airstrikes on Oct. 27 against similar targets in eastern Syria failed to deter Iran or its proxies in Syria and Iraq, which the Biden administration has blamed for the attacks. Not only have the attacks continued â€” there have been at least 22 more since the American retaliatory strikes last month â€” but Pentagon officials said they have become more dangerous. Iran-backed militias have packed even larger loads of explosives â€” more than 80 pounds â€” onto drones launched at American bases, U.S. officials said. â€œThis precision self-defense strike is a response to a series of attacks against U.S. personnel in Iraq and Syria by I.R.G.C.-Quds Force affiliates,â€ Defense Secretary Lloyd J. Austin III said in a statement. â€œThe president has no higher priority than the safety of U.S. personnel, and he directed todayâ€™s action to make clear that the United States will defend itself, its personnel, and its interests.â€ â€œThe United States is fully prepared to take further necessary measures to protect our people and our facilities,â€ he added. â€œWe urge against any escalation.â€ The strikes also came after the Pentagon said a U.S. military MQ-9 Reaper surveillance drone was shot down over the Red Sea off the coast of Yemen on Wednesday by Iran-backed Houthi rebels. The downing of the drone, the mainstay of the American militaryâ€™s aerial surveillance fleet, was another escalation of violence between the United States and Iran-backed groups in the region. The episode underscored the risks that the conflict between Israel and the Palestinian group Hamas could spiral into a wider war. Biden administration officials have been trying to calculate how to deter the Iranian-backed Shiite militias from attacking American troops in the region without sparking that broader conflict, said three administration officials, who spoke on the condition of anonymity to discuss internal planning. â€œThe attacks, the threats coming from militia that are aligned with Iran, are totally unacceptable,â€ Secretary of State Antony J. Blinken said in Iraq on Sunday. The Pentagon said on Wednesday that there had been at least 41 attacks on U.S. forces in Syria and Iraq since Oct. 17 and that at least 46 U.S. service members had been injured, 25 of whom had suffered traumatic brain injuries. The United States has 2,500 troops in Iraq and 900 in Syria, mostly to help local forces fight remnants of the Islamic State. In meetings to select targets, U.S. officials try to game out what response each strike will bring, one official said. Military officials at the Pentagonâ€™s Central Command and in the American intelligence community have a good idea where many militia leaders are, two officials said, and have, in the past two weeks, considered the possible blowback if targeted airstrikes were to kill those leaders. The effort to calibrate retaliation is inexact, the officials acknowledged. The strike against the weapons warehouse early Thursday was aimed at â€œdisrupting and degradingâ€ the abilities of the militias to carry out attacks against American troops, a senior Pentagon official told reporters after the strike. But the strike was carried out late at night in Syria when the chances of hitting any Iranian personnel or militia fighters were small, Pentagon officials said. | G203: 0 | H203: 0 | I203: 0 | J203: 0 | K203: 0 | L203: 0 | M203: 0 | N203: 0 | O203: 0 | P203: 10 | Q203: 621 | R203: 0.368 | S203: 0.191 | T203: 0.448 | U203: 0.5 | V203: 0.5 | W203: 0.073 | X203: 0.073 | Y203: 0.073 | Z203: 0.5 | AA203: 0.5 | AB203: 0.5 | AC203: 0.2795 | AD203: Title: U.S. Strikes Iran-Linked Facility in Syria in Round of Retaliation. Title: U.S. Strikes Iran-Linked Facility in Syria in Round of Retaliation. First Paragraph: Drone and rocket attacks on U.S. forces have continued in recent weeks, prompting a second round of retaliatory airstrikes in eastern Syria. For the second time in nearly two weeks, the United States carried out airstrikes against a facility used by Iranâ€™s Islamic Revolutionary Guards Corps and its proxies in eastern Syria early Thursday, ratcheting up retaliation for a steady stream of rocket and drone attacks against American forces in Iraq and Syria. The strikes by two Air Force F-15E jets against a weapons warehouse in Deir al Zour Province, Syria, came after U.S. airstrikes on Oct. 27 against similar targets in eastern Syria failed to deter Iran or its proxies in Syria and Iraq, which the Biden administration has blamed for the attacks. Not only have the attacks continued â€” there have been at least 22 more since the American retaliatory strikes last month â€” but Pentagon officials said they have become more dangerous. Iran-backed militias have packed even larger loads of explosives â€” more than 80 pounds â€” onto drones launched at American bases, U.S. officials said. â€œThis precision self-defense strike is a response to a series of attacks against U.S. personnel in Iraq and Syria by I.R.G.C.-Quds Force affiliates,â€ Defense Secretary Lloyd J. Austin III said in a statement. â€œThe president has no higher priority than the safety of U.S. personnel, and he directed todayâ€™s action to make clear that the United States will defend itself, its personnel, and its interests.â€ â€œThe United States is fully prepared to take further necessary measures to protect our people and our facilities,â€ he added. â€œWe urge against any escalation.â€ The strikes also came after the Pentagon said a U.S. military MQ-9 Reaper surveillance drone was shot down over the Red Sea off the coast of Yemen on Wednesday by Iran-backed Houthi rebels. The downing of the drone, the mainstay of the American militaryâ€™s aerial surveillance fleet, was another escalation of violence between the United States and Iran-backed groups in the region. The episode underscored the risks that the conflict between Israel and the Palestinian group Hamas could spiral into a wider war. Biden administration officials have been trying to calculate how to deter the Iranian-backed Shiite militias from attacking American troops in the region without sparking that broader conflict, said three administration officials, who spoke on the condition of anonymity to discuss internal planning. â€œThe attacks, the threats coming from militia that are aligned with Iran, are totally unacceptable,â€ Secretary of State Antony J. Blinken said in Iraq on Sunday. The Pentagon said on Wednesday that there had been at least 41 attacks on U.S. forces in Syria and Iraq since Oct. 17 and that at least 46 U.S. service members had been injured, 25 of whom had suffered traumatic brain injuries. The United States has 2,500 troops in Iraq and 900 in Syria, mostly to help local forces fight remnants of the Islamic State. In meetings to select targets, U.S. officials try to game out what response each strike will bring, one official said. Military officials at the Pentagonâ€™s Central Command and in the American intelligence community have a good idea where many militia leaders are, two officials said, and have, in the past two weeks, considered the possible blowback if targeted airstrikes were to kill those leaders. The effort to calibrate retaliation is inexact, the officials acknowledged. The strike against the weapons warehouse early Thursday was aimed at â€œdisrupting and degradingâ€ the abilities of the militias to carry out attacks against American troops, a senior Pentagon official told reporters after the strike. But the strike was carried out late at night in Syria when the chances of hitting any Iranian personnel or militia fighters were small, Pentagon officials said. | AE203: 45238 | AF203: 45238 | AG203: 2023 | AH203: syria | AI203: pentagon | AJ203: iran
